#VRML_SIM R2019a utf8
WorldInfo {
}
Viewpoint {
  orientation -0.08473185494528465 0.9845891103465255 0.15298626260082515 2.143110712092252
  position 2.5663930278310176 2.7855768743542137 -1.059051883099095
}
TexturedBackground {
}
TexturedBackgroundLight {
}
Floor {
}
Solid {
  children [
    DEF columpio_ Group {
      children [
        DEF A Group {
          children [
            Transform {
              translation 0 0.947 0
              rotation 0 0 1 0.349066
              children [
                DEF sloped_foot Shape {
                  appearance DEF gray_ PBRAppearance {
                    baseColor 0.3333333333333333 0.3411764705882353 0.3254901960784314
                    roughness 1
                    metalness 0
                  }
                  geometry Box {
                    size 0.04 2 0.1
                  }
                }
              ]
            }
            Transform {
              translation -0.68 0.947 0
              rotation 0 0 1 -0.349066
              children [
                USE sloped_foot
              ]
            }
            Transform {
              translation -0.34 0.65 0
              children [
                Shape {
                  appearance USE gray_
                  geometry Box {
                    size 0.9 0.04 0.1
                  }
                }
              ]
            }
          ]
        }
        Transform {
          translation 0 0 2
          children [
            USE A
            Transform {
              translation -0.34 1.86 -1
              children [
                Shape {
                  appearance USE gray_
                  geometry Box {
                    size 0.04 0.05 2
                  }
                }
              ]
            }
          ]
        }
      ]
    }
    HingeJoint {
      jointParameters HingeJointParameters {
        axis 0 1 0
        anchor -0.34 1.81 1
      }
      endPoint Solid {
        translation -0.34 1.81 1
        children [
          Shape {
            appearance DEF Green_ PBRAppearance {
              baseColor 0.45098039215686275 0.8235294117647058 0.08627450980392157
              roughness 1
              metalness 0
            }
            geometry Box {
              size 0.15 0.05 0.8
            }
          }
          HingeJoint {
            jointParameters HingeJointParameters {
              axis 0 0 1
              anchor 0 -0.025 0
              minStop -0.785398
              maxStop 0.785398
            }
            endPoint Solid {
              translation 0 -0.225 0
              rotation 0 0 1 0
              children [
                Group {
                  children [
                    Shape {
                      appearance DEF Orange_ PBRAppearance {
                        baseColor 0.9607843137254902 0.4745098039215686 0
                        roughness 1
                        metalness 0
                      }
                      geometry Cylinder {
                        height 0.4
                        radius 0.04
                      }
                    }
                    Transform {
                      translation 0 -0.2 0
                      children [
                        Shape {
                          appearance DEF Yellow PBRAppearance {
                            baseColor 0.9294117647058824 0.8313725490196079 0
                            roughness 1
                            metalness 0
                          }
                          geometry Sphere {
                            radius 0.08
                          }
                        }
                      ]
                    }
                  ]
                }
              ]
              physics Physics {
              }
            }
          }
        ]
        physics Physics {
        }
      }
    }
  ]
}
