#VRML_SIM R2019a utf8
WorldInfo {
}
Viewpoint {
  orientation -0.26957499264688634 0.9489306370919623 0.1638901135751442 1.1395857068604982
  position 2.6594377169990944 2.9938847143523883 2.9494063205639547
}
TexturedBackground {
}
TexturedBackgroundLight {
}
Floor {
}
Solid {
  children [
    DEF columpio_ Group {
      children [
        DEF A Group {
          children [
            Transform {
              translation 0 0.947 0
              rotation 0 0 1 0.349066
              children [
                DEF sloped_foot Shape {
                  appearance DEF gray_ PBRAppearance {
                    baseColor 0.3333333333333333 0.3411764705882353 0.3254901960784314
                    roughness 1
                    metalness 0
                  }
                  geometry Box {
                    size 0.04 2 0.1
                  }
                }
              ]
            }
            Transform {
              translation -0.68 0.947 0
              rotation 0 0 1 -0.349066
              children [
                USE sloped_foot
              ]
            }
            Transform {
              translation -0.34 0.65 0
              children [
                Shape {
                  appearance USE gray_
                  geometry Box {
                    size 0.9 0.04 0.1
                  }
                }
              ]
            }
          ]
        }
        Transform {
          translation 0 0 2
          children [
            USE A
            Transform {
              translation -0.34 1.86 -1
              children [
                Shape {
                  appearance USE gray_
                  geometry Box {
                    size 0.04 0.05 2
                  }
                }
              ]
            }
          ]
        }
      ]
    }
    HingeJoint {
      jointParameters HingeJointParameters {
        axis 0 1 0
        anchor -0.34 1.81 1
      }
      endPoint Solid {
        translation -0.34 1.81 1
        children [
          Shape {
            appearance DEF Green_ PBRAppearance {
              baseColor 0.45098039215686275 0.8235294117647058 0.08627450980392157
              roughness 1
              metalness 0
            }
            geometry Box {
              size 0.15 0.05 0.8
            }
          }
        ]
        physics Physics {
        }
      }
    }
  ]
}
